Workbook
Name Slicer_Discount_Category: #N/A
Name Slicer_Price_Category: #N/A
Name Slicer_Rating_Category: #N/A

Sheet Dashboard
A1: Jumia Product Performance Dashboard
A3: Pricing • Discounts • Customer Reviews • Product Performance
A9: TOP 10 PRODUCTS BY REVIEWS | H9: TOP 10 PRODUCTS BY RATING | O9: TOP 10 PRODUCTS BY DISCOUNT
A10: Product | F10: Reviews | H10: Product | M10: Rating | O10: Product | T10: Discount
A11: 120W Cordless Vacuum Cleaners Handheld Electric Vacuum Cleaner | F11: 69 | H11: Classic Black Cat Cotton Hemp Pillow Case For Home Car | M11: 5 | O11: 6 In 1 Bottle Can Opener Multifunctional Easy Opener | T11: 0.64
A12: 137 Pieces Cake Decorating Tool Set Baking Supplies | F12: 55 | H12: LASA Aluminum Folding Truck Hand Cart - 68kg Max | M12: 5 | O12: LASA FOLDING TABLE SERVING STAND | T12: 0.55
A13: Electronic Digital Display Vernier Caliper | F13: 49 | H13: Konka Healty Electric Kettle, 24-hour Heat Preservation,1.5L,800W, White | M13: 5 | O13: 5-PCS Stainless Steel Cooking Pot Set With Steamed Slices | T13: 0.55
A14: 3D Waterproof EVA Plastic Shower Curtain 1.8*2Mtrs | F14: 44 | H14: Anti-Skid Absorbent Insulation Coaster For Home Office | M14: 5 | O14: Creative Owl Shape Keychain Black | T14: 0.55
A15: 100 Pcs Crochet Hook Tool Set Knitting Hook Set With Box | F15: 39 | H15: Peacock Throw Pillow Cushion Case For Home Car | M15: 5 | O15: LASA 3 Tier Bamboo Shoe Bench Storage Shelf | T15: 0.54
A16: Punch-free Great Load Bearing Bathroom Storage Rack Wall Shelf-White | F16: 36 | H16: Bedroom Simple Floor Hanging Clothes Rack Single Pole Hat Rack - White | M16: 5 | O16: Mythco 120COB Solar Wall Ligt With Motion Sensor And Remote Control 3 Modes | T16: 0.54
A17: 53 Pieces/Set Yarn Knitting Crochet Hooks With Bag - Pansies | F17: 32 | H17: DIY File Folder, Office Drawer File Holder, Pen Holder, Desktop Storage Rack | M17: 5 | O17: Classic Black Cat Cotton Hemp Pillow Case For Home Car | T17: 0.53
A18: Portable Mini Cordless Car Vacuum Cleaner - Blue | F18: 24 | H18: LASA FOLDING TABLE SERVING STAND | M18: 4.8 | O18: 3PCS Single Head Knitting Crochet Sweater Needle Set | T18: 0.53
A19: 53Pcs/Set Yarn Knitting Crochet Hooks With Bag - Fortune Cat | F19: 20 | H19: Portable Home Small Air Humidifier 3-Speed Fan - Green | M19: 4.8 | O19: Exfoliate And Exfoliate Face Towel - Black | T19: 0.52
A20: 52 Pieces Cake Decorating Tool Set Gift Kit Baking Supplies | F20: 20 | H20: 40cm Gold DIY Acrylic Wall Sticker Clock | M20: 4.8 | O20: Intelligent LED Body Sensor Wireless Lighting Night Light USB | T20: 0.52

Sheet Raw dataset
A1: Product | B1: Current price | C1: old price | D1: Discount | E1: Review | F1: Ratingd
A2: 115 Piece Set Of Multifunctional Precision Screwdrivers | B2: KSh 950 | C2: KSh 1,525 | D2: 0.38 | E2: -2 | F2: 4.5 out of 5
A3: Metal Decorative Hooks Key Hangers Entryway Wall Hooks Towel Hooks - Home | B3: KSh 527 | C3: KSh 999 | D3: 0.47 | E3: -14 | F3: 4.1 out of 5
A4: Portable Mini Cordless Car Vacuum Cleaner - Blue | B4: KSh 2,199 | C4: KSh 2,923 | D4: 0.25 | E4: -24 | F4: 4.6 out of 5
A5: Weighing Scale Digital Bathroom Body Fat Scale USB-Black | B5: KSh 1,580 | C5: KSh 2,499 | D5: 0.37 | E5: -7 | F5: 4.7 out of 5
A6: Portable Home Small Air Humidifier 3-Speed Fan - Green | B6: KSh 1,740 | C6: KSh 2,356 | D6: 0.26 | E6: -5 | F6: 4.8 out of 5
A7: 220V 60W Electric Soldering Iron Kits With Tools, Tips, And Multimeter | B7: KSh 2,999 | C7: KSh 3,290 | D7: 0.09 | E7: -15 | F7: 4 out of 5
A8: 137 Pieces Cake Decorating Tool Set Baking Supplies | B8: KSh 2,319 | C8: KSh 3,032 | D8: 0.24 | E8: -55 | F8: 4.6 out of 5
A9: Desk Foldable Fan Adjustable Fan Strong Wind 3 Gear Usb | B9: KSh 988 | C9: KSh 1,580 | D9: 0.37 | E9: -2 | F9: 4 out of 5
A10: LASA FOLDING TABLE SERVING STAND | B10: KSh 1,274 | C10: KSh 2,800 | D10: 0.55 | E10: -5 | F10: 4.8 out of 5
A11: 13 In 1 Home Repair Tools Box Kit Set | B11: KSh 1,600 | C11: KSh 2,929 | D11: 0.45 | E11: -5 | F11: 3.8 out of 5
A12: Genebre 115 In 1 Screwdriver Repairing Tool Set For IPhone Cellphone Hand Tool | B12: KSh 799 | C12: KSh 999 | D12: 0.2 | E12: -12 | F12: 4.1 out of 5
A13: 100 Pcs Crochet Hook Tool Set Knitting Hook Set With Box | B13: KSh 990 | C13: KSh 1,500 | D13: 0.34 | E13: -39 | F13: 4.7 out of 5
... A22: 3PCS Single Head Knitting Crochet Sweater Needle Set | B22: KSh 38 | C22: KSh 80 | D22: 0.53 | E22: -13 | F22: 3.3 out of 5
A23: 4pcs Bathroom/Kitchen Towel Rack,Roll Paper Holder,Towel Bars,Hook | B23: KSh 1,860 | C23: KSh 3,220 | D23: 0.42
A24: LED Romantic Spaceship Starry Sky Projector,Children's Bedroom Night Light-Blue | B24: KSh 880 | C24: KSh 1,350 | D24: 0.35 | E24: -6 | F24: 4 out of 5
A25: Foldable Overbed Table/Desk | B25: KSh 1,650 | C25: KSh 2,150 | D25: 0.23 | E25: -14 | F25: 4.4 out of 5
A26: LASA 3 Tier Bamboo Shoe Bench Storage Shelf | B26: KSh 2,048 | C26: KSh 4,500 | D26: 0.54 | E26: -7 | F26: 4.3 out of 5
A27: Electronic Digital Display Vernier Caliper | B27: KSh 420 | C27: KSh 647 | D27: 0.35 | E27: -49 | F27: 4.6 out of 5
A28: Portable Wardrobe Nonwoven With 3 Hanging Rods And 6 Storage Shelves | B28: KSh 2,880 | C28: KSh 3,520 | D28: 0.18 | E28: -12 | F28: 3.8 out of 5
A29: 12 Litre Black Insulated Lunch Box | B29: KSh 1,350 | C29: KSh 1,990 | D29: 0.32 | E29: -13 | F29: 3.8 out of 5
A30: 52 Pieces Cake Decorating Tool Set Gift Kit Baking Supplies | B30: KSh 1,758 | C30: KSh 2,499 | D30: 0.3 | E30: -20 | F30: 4.1 out of 5
A31: MultiFunctional Storage Rack Multi-layer Bookshelf | B31: KSh 2,200 | C31: KSh 4,080 | D31: 0.46
A32: Exfoliate And Exfoliate Face Towel - Black | B32: KSh 185 | C32: KSh 382 | D32: 0.52 | E32: -9 | F32: 4.3 out of 5
A33: 12 Litre Insulated Lunch Box Grey | B33: KSh 980 | C33: KSh 1,490 | D33: 0.34 | E33: -12 | F33: 4.7 out of 5
A34: LED Eye Protection Desk Lamp , Study, Reading, USB Fan - Double Pen Holder | B34: KSh 1,820 | C34: KSh 3,490 | D34: 0.48 | E34: -9 | F34: 4.3 out of 5
A35: 53Pcs/Set Yarn Knitting Crochet Hooks With Bag - Fortune Cat | B35: KSh 1,940 | C35: KSh 2,650 | D35: 0.27 | E35: -20 | F35: 4.7 out of 5
A36: 53 Pieces/Set Yarn Knitting Crochet Hooks With Bag - Pansies | B36: KSh 1,980 | C36: KSh 2,699 | D36: 0.27 | E36: -32 | F36: 4.5 out of 5
A37: DIY File Folder, Office Drawer File Holder, Pen Holder, Desktop Storage Rack | B37: KSh 1,620 | C37: KSh 2,690 | D37: 0.4 | E37: -1 | F37: 5 out of 5
A38: Classic Black Cat Cotton Hemp Pillow Case For Home Car | B38: KSh 171 | C38: KSh 360 | D38: 0.53 | E38: -2 | F38: 5 out of 5
A39: Punch-free Great Load Bearing Bathroom Storage Rack Wall Shelf-White | B39: KSh 389 | C39: KSh 656 | D39: 0.41 | E39: -36 | F39: 4.3 out of 5
A40: 1/2/3 Seater Elastic Sofa Cover,Living Room/Home Decor Chair Cover-Grey | B40: KSh 1,620 - KSh 1,980 | C40: KSh 2,200 - KSh 3,200 | D40: 0.38 | E40: -2 | F40: 4.5 out of 5
A41: LASA Stainless Steel Double Wall Mount Soap Dispenser - 500ml | B41: KSh 2,750 | C41: KSh 4,471 | D41: 0.38
A42: 4M Float Switch Water Level Controller -Water Tank | B42: KSh 475 | C42: KSh 931 | D42: 0.49
A43: Modern Sofa Throw Pillow Cover-45x45cm-Blue&Red | B43: KSh 238 | C43: KSh 476 | D43: 0.5
A44: Balloon Insert, Birthday Party Balloon Set, PU Leather | B44: KSh 610 | C44: KSh 1,060 | D44: 0.42
A45: Balloon Insert, Birthday Party Balloon Set, PU Leather | B45: KSh 610 | C45: KSh 1,060 | D45: 0.42
A46: Shower Cap Wide Elastic Band Cover Reusable Bashroom Cap | B46: KSh 2,132 | C46: KSh 2,169 | D46: 0.02
A47: Christmas Elk Fence Yard Lawn Decorations Cute For Holidays | B47: KSh 999 | C47: KSh 2,000 | D47: 0.5
A48: 60W Hot Melt Glue Sprayer - Efficient And Stable Glue Dispensing | B48: KSh 1,190 | C48: KSh 1,785 | D48: 0.33
...

Sheet Cleaned data
A1: Product | B1: Current price | C1: Old price | D1: Discount | E1: Review | F1: Rating
A2: 115 Piece Set Of Multifunctional Precision Screwdrivers | B2: 950 | C2: 1525 | D2: 0.38 | E2: 2 | F2: 4.5
A3: Metal Decorative Hooks Key Hangers Entryway Wall Hooks Towel Hooks - Home | B3: 527 | C3: 999 | D3: 0.47 | E3: 14 | F3: 4.1
A4: Portable Mini Cordless Car Vacuum Cleaner - Blue | B4: 2199 | C4: 2923 | D4: 0.25 | E4: 24 | F4: 4.6
A5: Weighing Scale Digital Bathroom Body Fat Scale USB-Black | B5: 1580 | C5: 2499 | D5: 0.37 | E5: 7 | F5: 4.7
A6: Portable Home Small Air Humidifier 3-Speed Fan - Green | B6: 1740 | C6: 2356 | D6: 0.26 | E6: 5 | F6: 4.8
A7: 220V 60W Electric Soldering Iron Kits With Tools, Tips, And Multimeter | B7: 2999 | C7: 3290 | D7: 0.09 | E7: 15 | F7: 4
A8: 137 Pieces Cake Decorating Tool Set Baking Supplies | B8: 2319 | C8: 3032 | D8: 0.24 | E8: 55 | F8: 4.6
A9: Desk Foldable Fan Adjustable Fan Strong Wind 3 Gear Usb | B9: 988 | C9: 1580 | D9: 0.37 | E9: 2 | F9: 4
A10: LASA FOLDING TABLE SERVING STAND | B10: 1274 | C10: 2800 | D10: 0.55 | E10: 5 | F10: 4.8
A11: 13 In 1 Home Repair Tools Box Kit Set | B11: 1600 | C11: 2929 | D11: 0.45 | E11: 5 | F11: 3.8
A12: Genebre 115 In 1 Screwdriver Repairing Tool Set For IPhone Cellphone Hand Tool | B12: 799 | C12: 999 | D12: 0.2 | E12: 12 | F12: 4.1
A13: 100 Pcs Crochet Hook Tool Set Knitting Hook Set With Box | B13: 990 | C13: 1500 | D13: 0.34 | E13: 39 | F13: 4.7
... A22: 3PCS Single Head Knitting Crochet Sweater Needle Set | B22: 38 | C22: 80 | D22: 0.53 | E22: 13 | F22: 3.3
A23: 4pcs Bathroom/Kitchen Towel Rack,Roll Paper Holder,Towel Bars,Hook | B23: 1860 | C23: 3220 | D23: 0.42 | E23: 0
A24: LED Romantic Spaceship Starry Sky Projector,Children's Bedroom Night Light-Blue | B24: 880 | C24: 1350 | D24: 0.35 | E24: 6 | F24: 4
A25: Foldable Overbed Table/Desk | B25: 1650 | C25: 2150 | D25: 0.23 | E25: 14 | F25: 4.4
A26: LASA 3 Tier Bamboo Shoe Bench Storage Shelf | B26: 2048 | C26: 4500 | D26: 0.54 | E26: 7 | F26: 4.3
A27: Electronic Digital Display Vernier Caliper | B27: 420 | C27: 647 | D27: 0.35 | E27: 49 | F27: 4.6
A28: Portable Wardrobe Nonwoven With 3 Hanging Rods And 6 Storage Shelves | B28: 2880 | C28: 3520 | D28: 0.18 | E28: 12 | F28: 3.8
A29: 12 Litre Black Insulated Lunch Box | B29: 1350 | C29: 1990 | D29: 0.32 | E29: 13 | F29: 3.8
A30: 52 Pieces Cake Decorating Tool Set Gift Kit Baking Supplies | B30: 1758 | C30: 2499 | D30: 0.3 | E30: 20 | F30: 4.1
A31: MultiFunctional Storage Rack Multi-layer Bookshelf | B31: 2200 | C31: 4080 | D31: 0.46 | E31: 0
A32: Exfoliate And Exfoliate Face Towel - Black | B32: 185 | C32: 382 | D32: 0.52 | E32: 9 | F32: 4.3
A33: 12 Litre Insulated Lunch Box Grey | B33: 980 | C33: 1490 | D33: 0.34 | E33: 12 | F33: 4.7
A34: LED Eye Protection Desk Lamp , Study, Reading, USB Fan - Double Pen Holder | B34: 1820 | C34: 3490 | D34: 0.48 | E34: 9 | F34: 4.3
A35: 53Pcs/Set Yarn Knitting Crochet Hooks With Bag - Fortune Cat | B35: 1940 | C35: 2650 | D35: 0.27 | E35: 20 | F35: 4.7
A36: 53 Pieces/Set Yarn Knitting Crochet Hooks With Bag - Pansies | B36: 1980 | C36: 2699 | D36: 0.27 | E36: 32 | F36: 4.5
A37: DIY File Folder, Office Drawer File Holder, Pen Holder, Desktop Storage Rack | B37: 1620 | C37: 2690 | D37: 0.4 | E37: 1 | F37: 5
A38: Classic Black Cat Cotton Hemp Pillow Case For Home Car | B38: 171 | C38: 360 | D38: 0.53 | E38: 2 | F38: 5
A39: Punch-free Great Load Bearing Bathroom Storage Rack Wall Shelf-White | B39: 389 | C39: 656 | D39: 0.41 | E39: 36 | F39: 4.3
A40: 1/2/3 Seater Elastic Sofa Cover,Living Room/Home Decor Chair Cover-Grey | B40: 1800 | C40: 2700 | D40: 0.38 | E40: 2 | F40: 4.5
A41: LASA Stainless Steel Double Wall Mount Soap Dispenser - 500ml | B41: 2750 | C41: 4471 | D41: 0.38 | E41: 0
A42: 4M Float Switch Water Level Controller -Water Tank | B42: 475 | C42: 931 | D42: 0.49 | E42: 0
A43: Modern Sofa Throw Pillow Cover-45x45cm-Blue&Red | B43: 238 | C43: 476 | D43: 0.5 | E43: 0
A44: Balloon Insert, Birthday Party Balloon Set, PU Leather | B44: 610 | C44: 1060 | D44: 0.42 | E44: 0
A45: Shower Cap Wide Elastic Band Cover Reusable Bashroom Cap | B45: 2132 | C45: 2169 | D45: 0.02 | E45: 0
A46: Christmas Elk Fence Yard Lawn Decorations Cute For Holidays | B46: 999 | C46: 2000 | D46: 0.5 | E46: 0
A47: 60W Hot Melt Glue Sprayer - Efficient And Stable Glue Dispensing | B47: 1190 | C47: 1785 | D47: 0.33 | E47: 0
A48: Car Phone Charging Stand | B48: 671 | C48: 1316 | D48: 0.49 | E48: 0
...

Sheet Cleaning log
A1: Cleaning Issue | B1: Finding in Raw Data | C1: Action Taken | D1: Validation / Final Result
A2: Record count | B2: 115 rows | C2: Used as starting population | D2: 115 raw records
A3: Exact duplicates | B3: 5 duplicate rows across 2 duplicate groups | C3: Removed 3 duplicate rows using Remove Duplicates; retained one original per group | D3: 112 records remain
A4: Missing Review | B4: 58 blanks in raw data; 55 after duplicates removed | C4: Blank Review → 0 because blank represents no reviews | D4: 0 Review blanks
A5: Negative Review | B5: 57 negative review values | C5: Converted negative values to positive counts | D5: 0 negative reviews
A6: Missing Rating | B6: 58 blanks in raw data; 55 after duplicates removed | C6: Blank Rating → remain blank / Not Rated | D6: 55 unrated products
A7: Rating text | B7: Values such as 4.6 out of 5 | C7: Extract numeric portion and convert to number | D7: 57 numeric ratings
A8: Rating validation | B8: Ratings actually range from 2.0 to 5.0 | C8: Validated against original source | D8: Min 2.0, Max 5.0
A9: Current Price | B9: Text with KSh, commas; 1 range | C9: Remove currency/commas; convert to number | D9: 1 range handled using midpoint
A10: Current Price range | B10: KSh 1,620 - KSh 1,980 | C10: (1620 + 1980) / 2 | D10: KSh 1,800
A11: Old Price | B11: Text with KSh, commas; 1 range | C11: Remove currency/commas; convert to number | D11: 1 range handled using midpoint
A12: Old Price range | B12: KSh 2,200 - KSh 3,200 | C12: (2200 + 3200) / 2 | D12: KSh 2,700
... A15: Other formatting issue | B15: Extra spaces in the price-range text | C15: Handled with TRIM() during price cleaning | D15: Clean numeric values
A18: Enrichment field | B18: Rule
A19: Discount Amount | B19: Old Price − Current Price
A20: Rating Category | B20: Poor <3; Average 3–4; Good >4–4.5; Excellent >4.5; blank = Not Rated
A21: Discount Category | B21: Low <20%; Medium 20–40%; High >40%
A22: Price Category | B22: Q1/Q3-based thresholds from Current Price distribution
B24: Min | C24: Q1 | D24: Median | E24: Q3 | F24: Max
B25: =MIN(Enrichment!B2:B113) -> 38 | C25: =_xlfn.QUARTILE.INC(Enrichment!B2:B113,1) -> 493 | D25: =MEDIAN(Enrichment!B2:B113) -> 998.5 | E25: =_xlfn.QUARTILE.INC(Enrichment!B2:B113,3) -> 1669.5 | F25: =MAX(Enrichment!B2:B113) -> 3750
A26: Category | B26: Rule
A27: Low | B27: ≤ KSh 493
A28: Medium | B28: > KSh 493 and ≤ KSh 1,669.50
A29: High | B29: > KSh 1,669.50
A32: Enrichment check | B32: Result
A33: Rating — Poor | B33: 12
A34: Rating — Average | B34: 13
A35: Rating — Good | B35: 13
A36: Rating — Excellent | B36: 19
A37: Rating — Not Rated | B37: 55
A38: Rating categories total | B38: 112
A39: Discount — Low | B39: 18
A40: Discount — Medium | B40: 32
A41: Discount — High | B41: 62
A42: Discount categories total | B42: 112
A43: Price — Low | B43: 28
A44: Price — Medium | B44: 56
... A46: Price categories total | B46: 112
A50: Metric | B50: Result
A51: Average Current Price | B51: KSh 1,186.893
...

Sheet Project Brief
A1: Item | B1: Answer
A2: Business question | B2: How are discounts related to customer ratings and reviews, and how do pricing strategies relate to product performance?
A3: Primary audience | B3: Jumia marketplace managers and sellers
A4: Main decisions | B4: Pricing and promotional strategy
A5: Key relationship 1 | B5: Discount vs Reviews
A6: Key relationship 2 | B6: Discount vs Rating
A7: Key relationship 3 | B7: Price vs Rating
A8: Key performance measures | B8: Rating, Reviews, Discount, Current Price
A11: Raw field | B11: Needs transformation? | C11: Why?
A12: Product | B12: No | C12: Text identifier; needs duplicate checking
A13: Current price | B13: Yes | C13: Text with KSh, commas and one price range
A14: Old price | B14: Yes | C14: Text with KSh, commas and one price range
A15: Discount | B15: To validate | C15: Source describes it as text percentage
A16: Review | B16: Yes | C16: Negative values and blanks
A17: Ratingd | B17: Yes | C17: Text such as 4.5 out of 5, plus blanks

Sheet Descriptive Stats
A1: Product | B1: Current price | C1: Old price | D1: Discount | E1: Review | F1: Rating
A2: 115 Piece Set Of Multifunctional Precision Screwdrivers | B2: 950 | C2: 1525 | D2: 0.38 | E2: 2 | F2: 4.5 | I2: Average Current Price | J2: =AVERAGE(B2:B113) -> 1186.8929
A3: Metal Decorative Hooks Key Hangers Entryway Wall Hooks Towel Hooks - Home | B3: 527 | C3: 999 | D3: 0.47 | E3: 14 | F3: 4.1 | I3: Average Old Price | J3: =AVERAGE(C2:C113) -> 1811.1071
A4: Portable Mini Cordless Car Vacuum Cleaner - Blue | B4: 2199 | C4: 2923 | D4: 0.25 | E4: 24 | F4: 4.6 | I4: Average Discount | J4: =AVERAGE(D2:D113) -> 0.36776786
A5: Weighing Scale Digital Bathroom Body Fat Scale USB-Black | B5: 1580 | C5: 2499 | D5: 0.37 | E5: 7 | F5: 4.7 | I5: Average Rating | J5: =AVERAGE(F2:F113) -> 3.8894737
A6: Portable Home Small Air Humidifier 3-Speed Fan - Green | B6: 1740 | C6: 2356 | D6: 0.26 | E6: 5 | F6: 4.8 | I6: Total Products | J6: =COUNTA(A2:A113) -> 112
A7: 220V 60W Electric Soldering Iron Kits With Tools, Tips, And Multimeter | B7: 2999 | C7: 3290 | D7: 0.09 | E7: 15 | F7: 4 | I7: Total Reviews | J7: =SUM(E2:E113) -> 723
A8: 137 Pieces Cake Decorating Tool Set Baking Supplies | B8: 2319 | C8: 3032 | D8: 0.24 | E8: 55 | F8: 4.6 | I8: Most Expensive Product | J8: =MAX(B2:B113) -> 3750 | K8: =INDEX(A2:A113,MATCH(MAX(B2:B113),B2:B113,0)) -> 32PCS Portable Cordless Drill Set With Cyclic Battery Drive -26 Variable Speed
A9: Desk Foldable Fan Adjustable Fan Strong Wind 3 Gear Usb | B9: 988 | C9: 1580 | D9: 0.37 | E9: 2 | F9: 4 | I9: Least Expensive Product | J9: =MIN(B2:B113) -> 38 | K9: =INDEX(A2:A113,MATCH(MIN(B2:B113),B2:B113,0)) -> 3PCS Single Head Knitting Crochet Sweater Needle Set
A10: LASA FOLDING TABLE SERVING STAND | B10: 1274 | C10: 2800 | D10: 0.55 | E10: 5 | F10: 4.8
A11: 13 In 1 Home Repair Tools Box Kit Set | B11: 1600 | C11: 2929 | D11: 0.45 | E11: 5 | F11: 3.8
A12: Genebre 115 In 1 Screwdriver Repairing Tool Set For IPhone Cellphone Hand Tool | B12: 799 | C12: 999 | D12: 0.2 | E12: 12 | F12: 4.1
A13: 100 Pcs Crochet Hook Tool Set Knitting Hook Set With Box | B13: 990 | C13: 1500 | D13: 0.34 | E13: 39 | F13: 4.7
A14: 40cm Gold DIY Acrylic Wall Sticker Clock | B14: 552 | C14: 1035 | D14: 0.47 | E14: 12 | F14: 4.8
A15: LASA Digital Thermometer And Hydrometer | B15: 501 | C15: 860 | D15: 0.42 | E15: 6 | F15: 4.5
A16: Multifunction Laser Level With Adjustment Tripod | B16: 1680 | C16: 2499 | D16: 0.33 | E16: 9 | F16: 4.2
A17: Anti-Skid Absorbent Insulation Coaster For Home Office | B17: 332 | C17: 684 | D17: 0.51 | E17: 2 | F17: 5
A18: Peacock Throw Pillow Cushion Case For Home Car | B18: 195 | C18: 360 | D18: 0.46 | E18: 2 | F18: 5
A19: LASA Aluminum Folding Truck Hand Cart - 68kg Max | B19: 2025 | C19: 3971 | D19: 0.49 | E19: 3 | F19: 5
A20: LED Wall Digital Alarm Clock Study Home 12 / 24H Clock Calendar | B20: 2999 | C20: 3699 | D20: 0.19 | E20: 5 | F20: 4.6
A21: 3D Waterproof EVA Plastic Shower Curtain 1.8*2Mtrs | B21: 998 | C21: 1966 | D21: 0.49 | E21: 44 | F21: 4.6
A22: 3PCS Single Head Knitting Crochet Sweater Needle Set | B22: 38 | C22: 80 | D22: 0.53 | E22: 13 | F22: 3.3
A23: 4pcs Bathroom/Kitchen Towel Rack,Roll Paper Holder,Towel Bars,Hook | B23: 1860 | C23: 3220 | D23: 0.42 | E23: 0
A24: LED Romantic Spaceship Starry Sky Projector,Children's Bedroom Night Light-Blue | B24: 880 | C24: 1350 | D24: 0.35 | E24: 6 | F24: 4
A25: Foldable Overbed Table/Desk | B25: 1650 | C25: 2150 | D25: 0.23 | E25: 14 | F25: 4.4
A26: LASA 3 Tier Bamboo Shoe Bench Storage Shelf | B26: 2048 | C26: 4500 | D26: 0.54 | E26: 7 | F26: 4.3
A27: Electronic Digital Display Vernier Caliper | B27: 420 | C27: 647 | D27: 0.35 | E27: 49 | F27: 4.6
A28: Portable Wardrobe Nonwoven With 3 Hanging Rods And 6 Storage Shelves | B28: 2880 | C28: 3520 | D28: 0.18 | E28: 12 | F28: 3.8
A29: 12 Litre Black Insulated Lunch Box | B29: 1350 | C29: 1990 | D29: 0.32 | E29: 13 | F29: 3.8
A30: 52 Pieces Cake Decorating Tool Set Gift Kit Baking Supplies | B30: 1758 | C30: 2499 | D30: 0.3 | E30: 20 | F30: 4.1
A31: MultiFunctional Storage Rack Multi-layer Bookshelf | B31: 2200 | C31: 4080 | D31: 0.46 | E31: 0
A32: Exfoliate And Exfoliate Face Towel - Black | B32: 185 | C32: 382 | D32: 0.52 | E32: 9 | F32: 4.3
A33: 12 Litre Insulated Lunch Box Grey | B33: 980 | C33: 1490 | D33: 0.34 | E33: 12 | F33: 4.7
A34: LED Eye Protection Desk Lamp , Study, Reading, USB Fan - Double Pen Holder | B34: 1820 | C34: 3490 | D34: 0.48 | E34: 9 | F34: 4.3
A35: 53Pcs/Set Yarn Knitting Crochet Hooks With Bag - Fortune Cat | B35: 1940 | C35: 2650 | D35: 0.27 | E35: 20 | F35: 4.7
A36: 53 Pieces/Set Yarn Knitting Crochet Hooks With Bag - Pansies | B36: 1980 | C36: 2699 | D36: 0.27 | E36: 32 | F36: 4.5
A37: DIY File Folder, Office Drawer File Holder, Pen Holder, Desktop Storage Rack | B37: 1620 | C37: 2690 | D37: 0.4 | E37: 1 | F37: 5
A38: Classic Black Cat Cotton Hemp Pillow Case For Home Car | B38: 171 | C38: 360 | D38: 0.53 | E38: 2 | F38: 5
A39: Punch-free Great Load Bearing Bathroom Storage Rack Wall Shelf-White | B39: 389 | C39: 656 | D39: 0.41 | E39: 36 | F39: 4.3
A40: 1/2/3 Seater Elastic Sofa Cover,Living Room/Home Decor Chair Cover-Grey | B40: 1800 | C40: 2700 | D40: 0.38 | E40: 2 | F40: 4.5
...

Sheet Enrichment
A1: Product | B1: Current price | C1: Old price | D1: Discount | E1: Review | F1: Rating | G1: Discount Amount | H1: Rating Category | I1: Discount Category | J1: Price Category | K1: Listing ID
A2: 120W Cordless Vacuum Cleaners Handheld Electric Vacuum Cleaner | B2: 445 | C2: 873 | D2: 0.49 | E2: 69 | F2: 2.8 | G2: =C2-B2 -> 428 | H2: =IF(F2="","Not Rated",IF(F2<3,"Poor",IF(F2<=4,"Average",IF(F2<=4.5,"Good","Excellent")))) -> Poor | I2: =IF(D2<20%,"Low",IF(D2<=40%,"Medium","High")) -> High | J2: =IF(B2<=493,"Low",IF(B2<=1669.5,"Medium","High")) -> Low | K2: =ROW()-1 -> 1
A3: 137 Pieces Cake Decorating Tool Set Baking Supplies | B3: 2319 | C3: 3032 | D3: 0.24 | E3: 55 | F3: 4.6 | G3: =C3-B3 -> 713 | H3: =IF(F3="","Not Rated",IF(F3<3,"Poor",IF(F3<=4,"Average",IF(F3<=4.5,"Good","Excellent")))) -> Excellent | I3: =IF(D3<20%,"Low",IF(D3<=40%,"Medium","High")) -> Medium | J3: =IF(B3<=493,"Low",IF(B3<=1669.5,"Medium","High")) -> High | K3: =ROW()-1 -> 2
A4: Electronic Digital Display Vernier Caliper | B4: 420 | C4: 647 | D4: 0.35 | E4: 49 | F4: 4.6 | G4: =C4-B4 -> 227 | H4: =IF(F4="","Not Rated",IF(F4<3,"Poor",IF(F4<=4,"Average",IF(F4<=4.5,"Good","Excellent")))) -> Excellent | I4: =IF(D4<20%,"Low",IF(D4<=40%,"Medium","High")) -> Medium | J4: =IF(B4<=493,"Low",IF(B4<=1669.5,"Medium","High")) -> Low | K4: =ROW()-1 -> 3
A5: 3D Waterproof EVA Plastic Shower Curtain 1.8*2Mtrs | B5: 998 | C5: 1966 | D5: 0.49 | E5: 44 | F5: 4.6 | G5: =C5-B5 -> 968 | H5: =IF(F5="","Not Rated",IF(F5<3,"Poor",IF(F5<=4,"Average",IF(F5<=4.5,"Good","Excellent")))) -> Excellent | I5: =IF(D5<20%,"Low",IF(D5<=40%,"Medium","High")) -> High | J5: =IF(B5<=493,"Low",IF(B5<=1669.5,"Medium","High")) -> Medium | K5: =ROW()-1 -> 4
A6: 100 Pcs Crochet Hook Tool Set Knitting Hook Set With Box | B6: 990 | C6: 1500 | D6: 0.34 | E6: 39 | F6: 4.7 | G6: =C6-B6 -> 510 | H6: =IF(F6="","Not Rated",IF(F6<3,"Poor",IF(F6<=4,"Average",IF(F6<=4.5,"Good","Excellent")))) -> Excellent | I6: =IF(D6<20%,"Low",IF(D6<=40%,"Medium","High")) -> Medium | J6: =IF(B6<=493,"Low",IF(B6<=1669.5,"Medium","High")) -> Medium | K6: =ROW()-1 -> 5
A7: Punch-free Great Load Bearing Bathroom Storage Rack Wall Shelf-White | B7: 389 | C7: 656 | D7: 0.41 | E7: 36 | F7: 4.3 | G7: =C7-B7 -> 267 | H7: =IF(F7="","Not Rated",IF(F7<3,"Poor",IF(F7<=4,"Average",IF(F7<=4.5,"Good","Excellent")))) -> Good | I7: =IF(D7<20%,"Low",IF(D7<=40%,"Medium","High")) -> High | J7: =IF(B7<=493,"Low",IF(B7<=1669.5,"Medium","High")) -> Low | K7: =ROW()-1 -> 6
A8: 53 Pieces/Set Yarn Knitting Crochet Hooks With Bag - Pansies | B8: 1980 | C8: 2699 | D8: 0.27 | E8: 32 | F8: 4.5 | G8: =C8-B8 -> 719 | H8: =IF(F8="","Not Rated",IF(F8<3,"Poor",IF(F8<=4,"Average",IF(F8<=4.5,"Good","Excellent")))) -> Good | I8: =IF(D8<20%,"Low",IF(D8<=40%,"Medium","High")) -> Medium | J8: =IF(B8<=493,"Low",IF(B8<=1669.5,"Medium","High")) -> High | K8: =ROW()-1 -> 7
A9: Portable Mini Cordless Car Vacuum Cleaner - Blue | B9: 2199 | C9: 2923 | D9: 0.25 | E9: 24 | F9: 4.6 | G9: =C9-B9 -> 724 | H9: =IF(F9="","Not Rated",IF(F9<3,"Poor",IF(F9<=4,"Average",IF(F9<=4.5,"Good","Excellent")))) -> Excellent | I9: =IF(D9<20%,"Low",IF(D9<=40%,"Medium","High")) -> Medium | J9: =IF(B9<=493,"Low",IF(B9<=1669.5,"Medium","High")) -> High | K9: =ROW()-1 -> 8
A10: 52 Pieces Cake Decorating Tool Set Gift Kit Baking Supplies | B10: 1758 | C10: 2499 | D10: 0.3 | E10: 20 | F10: 4.1 | G10: =C10-B10 -> 741 | H10: =IF(F10="","Not Rated",IF(F10<3,"Poor",IF(F10<=4,"Average",IF(F10<=4.5,"Good","Excellent")))) -> Good | I10: =IF(D10<20%,"Low",IF(D10<=40%,"Medium","High")) -> Medium | J10: =IF(B10<=493,"Low",IF(B10<=1669.5,"Medium","High")) -> High | K10: =ROW()-1 -> 9
A11: 53Pcs/Set Yarn Knitting Crochet Hooks With Bag - Fortune Cat | B11: 1940 | C11: 2650 | D11: 0.27 | E11: 20 | F11: 4.7 | G11: =C11-B11 -> 710 | H11: =IF(F11="","Not Rated",IF(F11<3,"Poor",IF(F11<=4,"Average",IF(F11<=4.5,"Good","Excellent")))) -> Excellent | I11: =IF(D11<20%,"Low",IF(D11<=40%,"Medium","High")) -> Medium | J11: =IF(B11<=493,"Low",IF(B11<=1669.5,"Medium","High")) -> High | K11: =ROW()-1 -> 10
A12: Agapeon Toothbrush Holder And Toothpaste Dispenser | B12: 382 | C12: 700 | D12: 0.45 | E12: 17 | F12: 2.6 | G12: =C12-B12 -> 318 | H12: =IF(F12="","Not Rated",IF(F12<3,"Poor",IF(F12<=4,"Average",IF(F12<=4.5,"Good","Excellent")))) -> Poor | I12: =IF(D12<20%,"Low",IF(D12<=40%,"Medium","High")) -> High | J12: =IF(B12<=493,"Low",IF(B12<=1669.5,"Medium","High")) -> Low | K12: =ROW()-1 -> 11
A13: VIC Wireless Vacuum Cleaner Dual Use For Home And Car 120W High Power Powerful | B13: 1220 | C13: 1555 | D13: 0.22 | E13: 16 | F13: 2.9 | G13: =C13-B13 -> 335 | H13: =IF(F13="","Not Rated",IF(F13<3,"Poor",IF(F13<=4,"Average",IF(F13<=4.5,"Good","Excellent")))) -> Poor | I13: =IF(D13<20%,"Low",IF(D13<=40%,"Medium","High")) -> Medium | J13: =IF(B13<=493,"Low",IF(B13<=1669.5,"Medium","High")) -> Medium | K13: =ROW()-1 -> 12
... A58: Wall-mounted Sticker Punch-free Plug Fixer | B58: 450 | C58: 900 | D58: 0.5 | E58: 1 | F58: 2 | G58: =C58-B58 -> 450 | H58: =IF(F58="","Not Rated",IF(F58<3,"Poor",IF(F58<=4,"Average",IF(F58<=4.5,"Good","Excellent")))) -> Poor | I58: =IF(D58<20%,"Low",IF(D58<=40%,"Medium","High")) -> High | J58: =IF(B58<=493,"Low",IF(B58<=1669.5,"Medium","High")) -> Low | K58: =ROW()-1 -> 57
A59: 4pcs Bathroom/Kitchen Towel Rack,Roll Paper Holder,Towel Bars,Hook | B59: 1860 | C59: 3220 | D59: 0.42 | E59: 0 | G59: =C59-B59 -> 1360 | H59: =IF(F59="","Not Rated",IF(F59<3,"Poor",IF(F59<=4,"Average",IF(F59<=4.5,"Good","Excellent")))) -> Not Rated | I59: =IF(D59<20%,"Low",IF(D59<=40%,"Medium","High")) -> High | J59: =IF(B59<=493,"Low",IF(B59<=1669.5,"Medium","High")) -> High | K59: =ROW()-1 -> 58
A60: MultiFunctional Storage Rack Multi-layer Bookshelf | B60: 2200 | C60: 4080 | D60: 0.46 | E60: 0 | G60: =C60-B60 -> 1880 | H60: =IF(F60="","Not Rated",IF(F60<3,"Poor",IF(F60<=4,"Average",IF(F60<=4.5,"Good","Excellent")))) -> Not Rated | I60: =IF(D60<20%,"Low",IF(D60<=40%,"Medium","High")) -> High | J60: =IF(B60<=493,"Low",IF(B60<=1669.5,"Medium","High")) -> High | K60: =ROW()-1 -> 59
A61: LASA Stainless Steel Double Wall Mount Soap Dispenser - 500ml | B61: 2750 | C61: 4471 | D61: 0.38 | E61: 0 | G61: =C61-B61 -> 1721 | H61: =IF(F61="","Not Rated",IF(F61<3,"Poor",IF(F61<=4,"Average",IF(F61<=4.5,"Good","Excellent")))) -> Not Rated | I61: =IF(D61<20%,"Low",IF(D61<=40%,"Medium","High")) -> Medium | J61: =IF(B61<=493,"Low",IF(B61<=1669.5,"Medium","High")) -> High | K61: =ROW()-1 -> 60
A62: 4M Float Switch Water Level Controller -Water Tank | B62: 475 | C62: 931 | D62: 0.49 | E62: 0 | G62: =C62-B62 -> 456 | H62: =IF(F62="","Not Rated",IF(F62<3,"Poor",IF(F62<=4,"Average",IF(F62<=4.5,"Good","Excellent")))) -> Not Rated | I62: =IF(D62<20%,"Low",IF(D62<=40%,"Medium","High")) -> High | J62: =IF(B62<=493,"Low",IF(B62<=1669.5,"Medium","High")) -> Low | K62: =ROW()-1 -> 61
A63: Modern Sofa Throw Pillow Cover-45x45cm-Blue&Red | B63: 238 | C63: 476 | D63: 0.5 | E63: 0 | G63: =C63-B63 -> 238 | H63: =IF(F63="","Not Rated",IF(F63<3,"Poor",IF(F63<=4,"Average",IF(F63<=4.5,"Good","Excellent")))) -> Not Rated | I63: =IF(D63<20%,"Low",IF(D63<=40%,"Medium","High")) -> High | J63: =IF(B63<=493,"Low",IF(B63<=1669.5,"Medium","High")) -> Low | K63: =ROW()-1 -> 62
A64: Balloon Insert, Birthday Party Balloon Set, PU Leather | B64: 610 | C64: 1060 | D64: 0.42 | E64: 0 | G64: =C64-B64 -> 450 | H64: =IF(F64="","Not Rated",IF(F64<3,"Poor",IF(F64<=4,"Average",IF(F64<=4.5,"Good","Excellent")))) -> Not Rated | I64: =IF(D64<20%,"Low",IF(D64<=40%,"Medium","High")) -> High | J64: =IF(B64<=493,"Low",IF(B64<=1669.5,"Medium","High")) -> Medium | K64: =ROW()-1 -> 63
A65: Shower Cap Wide Elastic Band Cover Reusable Bashroom Cap | B65: 2132 | C65: 2169 | D65: 0.02 | E65: 0 | G65: =C65-B65 -> 37 | H65: =IF(F65="","Not Rated",IF(F65<3,"Poor",IF(F65<=4,"Average",IF(F65<=4.5,"Good","Excellent")))) -> Not Rated | I65: =IF(D65<20%,"Low",IF(D65<=40%,"Medium","High")) -> Low | J65: =IF(B65<=493,"Low",IF(B65<=1669.5,"Medium","High")) -> High | K65: =ROW()-1 -> 64
A66: Christmas Elk Fence Yard Lawn Decorations Cute For Holidays | B66: 999 | C66: 2000 | D66: 0.5 | E66: 0 | G66: =C66-B66 -> 1001 | H66: =IF(F66="","Not Rated",IF(F66<3,"Poor",IF(F66<=4,"Average",IF(F66<=4.5,"Good","Excellent")))) -> Not Rated | I66: =IF(D66<20%,"Low",IF(D66<=40%,"Medium","High")) -> High | J66: =IF(B66<=493,"Low",IF(B66<=1669.5,"Medium","High")) -> Medium | K66: =ROW()-1 -> 65
A67: 60W Hot Melt Glue Sprayer - Efficient And Stable Glue Dispensing | B67: 1190 | C67: 1785 | D67: 0.33 | E67: 0 | G67: =C67-B67 -> 595 | H67: =IF(F67="","Not Rated",IF(F67<3,"Poor",IF(F67<=4,"Average",IF(F67<=4.5,"Good","Excellent")))) -> Not Rated | I67: =IF(D67<20%,"Low",IF(D67<=40%,"Medium","High")) -> Medium | J67: =IF(B67<=493,"Low",IF(B67<=1669.5,"Medium","High")) -> Medium | K67: =ROW()-1 -> 66
A68: Car Phone Charging Stand | B68: 671 | C68: 1316 | D68: 0.49 | E68: 0 | G68: =C68-B68 -> 645 | H68: =IF(F68="","Not Rated",IF(F68<3,"Poor",IF(F68<=4,"Average",IF(F68<=4.5,"Good","Excellent")))) -> Not Rated | I68: =IF(D68<20%,"Low",IF(D68<=40%,"Medium","High")) -> High | J68: =IF(B68<=493,"Low",IF(B68<=1669.5,"Medium","High")) -> Medium | K68: =ROW()-1 -> 67
A69: 2pcs Solar Street Light Flood Light Outdoor | B69: 1200 | C69: 1950 | D69: 0.38 | E69: 0 | G69: =C69-B69 -> 750 | H69: =IF(F69="","Not Rated",IF(F69<3,"Poor",IF(F69<=4,"Average",IF(F69<=4.5,"Good","Excellent")))) -> Not Rated | I69: =IF(D69<20%,"Low",IF(D69<=40%,"Medium","High")) -> Medium | J69: =IF(B69<=493,"Low",IF(B69<=1669.5,"Medium","High")) -> Medium | K69: =ROW()-1 -> 68
A70: Creative Owl Shape Keychain Black | B70: 199 | C70: 504 | D70: 0.61 | E70: 0 | G70: =C70-B70 -> 305 | H70: =IF(F70="","Not Rated",IF(F70<3,"Poor",IF(F70<=4,"Average",IF(F70<=4.5,"Good","Excellent")))) -> Not Rated | I70: =IF(D70<20%,"Low",IF(D70<=40%,"Medium","High")) -> High | J70: =IF(B70<=493,"Low",IF(B70<=1669.5,"Medium","High")) -> Low | K70: =ROW()-1 -> 69
... A113: Black Simple Water Cup Wine Coaster Anti Slip Absorbent | B113: 169 | C113: 320 | D113: 0.47 | E113: 0 | G113: =C113-B113 -> 151 | H113: =IF(F113="","Not Rated",IF(F113<3,"Poor",IF(F113<=4,"Average",IF(F113<=4.5,"Good","Excellent")))) -> Not Rated | I113: =IF(D113<20%,"Low",IF(D113<=40%,"Medium","High")) -> High | J113: =IF(B113<=493,"Low",IF(B113<=1669.5,"Medium","High")) -> Low | K113: =ROW()-1 -> 112

Sheet Analysis Working
A1: Product | B1: Current price | C1: Old price | D1: Discount | E1: Review | F1: Rating | G1: Rating_Chart | H1: Review_Chart | I1: Price_Chart | J1: Rating_Chart 2 | M1: Correlation | N1: R2
A2: 120W Cordless Vacuum Cleaners Handheld Electric Vacuum Cleaner | B2: 445 | C2: 873 | D2: 0.49 | E2: 69 | F2: 2.8 | G2: =IF(F2="",NA(),F2) -> 2.8 | H2: =IF(F2="",NA(),E2) -> 69 | I2: =IF(F2="",NA(),B2) -> 445 | J2: =IF(F2="",NA(),F2) -> 2.8 | L2: Discount vs Reviews | M2: =CORREL(D2:D113,E2:E113) -> 0.012188797 | N2: 0.0001 | P2: =_xlfn.QUARTILE.INC(E2:E113,1) -> 0 | Q2: =_xlfn.QUARTILE.INC(E2:E113,3) -> 7 | R2: =MEDIAN(E2:E113) -> 1
A3: 137 Pieces Cake Decorating Tool Set Baking Supplies | B3: 2319 | C3: 3032 | D3: 0.24 | E3: 55 | F3: 4.6 | G3: =IF(F3="",NA(),F3) -> 4.6 | H3: =IF(F3="",NA(),E3) -> 55 | I3: =IF(F3="",NA(),B3) -> 2319 | J3: =IF(F3="",NA(),F3) -> 4.6 | L3: Rating vs Reviews | M3: =CORREL(F2:F113,E2:E113) -> 0.057209035 | N3: 0.0033
A4: Electronic Digital Display Vernier Caliper | B4: 420 | C4: 647 | D4: 0.35 | E4: 49 | F4: 4.6 | G4: =IF(F4="",NA(),F4) -> 4.6 | H4: =IF(F4="",NA(),E4) -> 49 | I4: =IF(F4="",NA(),B4) -> 420 | J4: =IF(F4="",NA(),F4) -> 4.6 | L4: Current Price vs Rating | M4: =CORREL(B2:B113,F2:F113) -> 0.11009021 | N4: 0.0121
A5: 3D Waterproof EVA Plastic Shower Curtain 1.8*2Mtrs | B5: 998 | C5: 1966 | D5: 0.49 | E5: 44 | F5: 4.6 | G5: =IF(F5="",NA(),F5) -> 4.6 | H5: =IF(F5="",NA(),E5) -> 44 | I5: =IF(F5="",NA(),B5) -> 998 | J5: =IF(F5="",NA(),F5) -> 4.6
A6: 100 Pcs Crochet Hook Tool Set Knitting Hook Set With Box | B6: 990 | C6: 1500 | D6: 0.34 | E6: 39 | F6: 4.7 | G6: =IF(F6="",NA(),F6) -> 4.7 | H6: =IF(F6="",NA(),E6) -> 39 | I6: =IF(F6="",NA(),B6) -> 990 | J6: =IF(F6="",NA(),F6) -> 4.7
A7: Punch-free Great Load Bearing Bathroom Storage Rack Wall Shelf-White | B7: 389 | C7: 656 | D7: 0.41 | E7: 36 | F7: 4.3 | G7: =IF(F7="",NA(),F7) -> 4.3 | H7: =IF(F7="",NA(),E7) -> 36 | I7: =IF(F7="",NA(),B7) -> 389 | J7: =IF(F7="",NA(),F7) -> 4.3 | L7: Top 10 by Discount
A8: 53 Pieces/Set Yarn Knitting Crochet Hooks With Bag - Pansies | B8: 1980 | C8: 2699 | D8: 0.27 | E8: 32 | F8: 4.5 | G8: =IF(F8="",NA(),F8) -> 4.5 | H8: =IF(F8="",NA(),E8) -> 32 | I8: =IF(F8="",NA(),B8) -> 1980 | J8: =IF(F8="",NA(),F8) -> 4.5 | L8: Product | M8: Discount
A9: Portable Mini Cordless Car Vacuum Cleaner - Blue | B9: 2199 | C9: 2923 | D9: 0.25 | E9: 24 | F9: 4.6 | G9: =IF(F9="",NA(),F9) -> 4.6 | H9: =IF(F9="",NA(),E9) -> 24 | I9: =IF(F9="",NA(),B9) -> 2199 | J9: =IF(F9="",NA(),F9) -> 4.6 | L9: 6 In 1 Bottle Can Opener Multifunctional Easy Opener | M9: 0.64
A10: 52 Pieces Cake Decorating Tool Set Gift Kit Baking Supplies | B10: 1758 | C10: 2499 | D10: 0.3 | E10: 20 | F10: 4.1 | G10: =IF(F10="",NA(),F10) -> 4.1 | H10: =IF(F10="",NA(),E10) -> 20 | I10: =IF(F10="",NA(),B10) -> 1758 | J10: =IF(F10="",NA(),F10) -> 4.1 | L10: Creative Owl Shape Keychain Black | M10: 0.61
A11: 53Pcs/Set Yarn Knitting Crochet Hooks With Bag - Fortune Cat | B11: 1940 | C11: 2650 | D11: 0.27 | E11: 20 | F11: 4.7 | G11: =IF(F11="",NA(),F11) -> 4.7 | H11: =IF(F11="",NA(),E11) -> 20 | I11: =IF(F11="",NA(),B11) -> 1940 | J11: =IF(F11="",NA(),F11) -> 4.7 | L11: LASA FOLDING TABLE SERVING STAND | M11: 0.55
A12: Agapeon Toothbrush Holder And Toothpaste Dispenser | B12: 382 | C12: 700 | D12: 0.45 | E12: 17 | F12: 2.6 | G12: =IF(F12="",NA(),F12) -> 2.6 | H12: =IF(F12="",NA(),E12) -> 17 | I12: =IF(F12="",NA(),B12) -> 382 | J12: =IF(F12="",NA(),F12) -> 2.6 | L12: Simple Metal Dog Art Sculpture Decoration For Home Office | M12: 0.55
A13: VIC Wireless Vacuum Cleaner Dual Use For Home And Car 120W High Power Powerful | B13: 1220 | C13: 1555 | D13: 0.22 | E13: 16 | F13: 2.9 | G13: =IF(F13="",NA(),F13) -> 2.9 | H13: =IF(F13="",NA(),E13) -> 16 | I13: =IF(F13="",NA(),B13) -> 1220 | J13: =IF(F13="",NA(),F13) -> 2.9 | L13: 5-PCS Stainless Steel Cooking Pot Set With Steamed Slices | M13: 0.55
A14: Intelligent LED Body Sensor Wireless Lighting Night Light USB | B14: 325 | C14: 680 | D14: 0.52 | E14: 15 | F14: 2.7 | G14: =IF(F14="",NA(),F14) -> 2.7 | H14: =IF(F14="",NA(),E14) -> 15 | I14: =IF(F14="",NA(),B14) -> 325 | J14: =IF(F14="",NA(),F14) -> 2.7 | L14: LASA 3 Tier Bamboo Shoe Bench Storage Shelf | M14: 0.54
A15: 220V 60W Electric Soldering Iron Kits With Tools, Tips, And Multimeter | B15: 2999 | C15: 3290 | D15: 0.09 | E15: 15 | F15: 4 | G15: =IF(F15="",NA(),F15) -> 4 | H15: =IF(F15="",NA(),E15) -> 15 | I15: =IF(F15="",NA(),B15) -> 2999 | J15: =IF(F15="",NA(),F15) -> 4 | L15: Mythco 120COB Solar Wall Ligt With Motion Sensor And Remote Control 3 Modes | M15: 0.54
A16: Metal Decorative Hooks Key Hangers Entryway Wall Hooks Towel Hooks - Home | B16: 527 | C16: 999 | D16: 0.47 | E16: 14 | F16: 4.1 | G16: =IF(F16="",NA(),F16) -> 4.1 | H16: =IF(F16="",NA(),E16) -> 14 | I16: =IF(F16="",NA(),B16) -> 527 | J16: =IF(F16="",NA(),F16) -> 4.1 | L16: 3PCS Single Head Knitting Crochet Sweater Needle Set | M16: 0.53
A17: Foldable Overbed Table/Desk | B17: 1650 | C17: 2150 | D17: 0.23 | E17: 14 | F17: 4.4 | G17: =IF(F17="",NA(),F17) -> 4.4 | H17: =IF(F17="",NA(),E17) -> 14 | I17: =IF(F17="",NA(),B17) -> 1650 | J17: =IF(F17="",NA(),F17) -> 4.4 | L17: Classic Black Cat Cotton Hemp Pillow Case For Home Car | M17: 0.53
A18: 5-PCS Stainless Steel Cooking Pot Set With Steamed Slices | B18: 2115 | C18: 4700 | D18: 0.55 | E18: 13 | F18: 2.1 | G18: =IF(F18="",NA(),F18) -> 2.1 | H18: =IF(F18="",NA(),E18) -> 13 | I18: =IF(F18="",NA(),B18) -> 2115 | J18: =IF(F18="",NA(),F18) -> 2.1 | L18: Exfoliate And Exfoliate Face Towel - Black | M18: 0.52
A19: 3PCS Single Head Knitting Crochet Sweater Needle Set | B19: 38 | C19: 80 | D19: 0.53 | E19: 13 | F19: 3.3 | G19: =IF(F19="",NA(),F19) -> 3.3 | H19: =IF(F19="",NA(),E19) -> 13 | I19: =IF(F19="",NA(),B19) -> 38 | J19: =IF(F19="",NA(),F19) -> 3.3
A20: 12 Litre Black Insulated Lunch Box | B20: 1350 | C20: 1990 | D20: 0.32 | E20: 13 | F20: 3.8 | G20: =IF(F20="",NA(),F20) -> 3.8 | H20: =IF(F20="",NA(),E20) -> 13 | I20: =IF(F20="",NA(),B20) -> 1350 | J20: =IF(F20="",NA(),F20) -> 3.8 | L20: Top 10 by Reviews
A21: 40cm Gold DIY Acrylic Wall Sticker Clock | B21: 552 | C21: 1035 | D21: 0.47 | E21: 12 | F21: 4.8 | G21: =IF(F21="",NA(),F21) -> 4.8 | H21: =IF(F21="",NA(),E21) -> 12 | I21: =IF(F21="",NA(),B21) -> 552 | J21: =IF(F21="",NA(),F21) -> 4.8 | L21: Product | M21: Review
A22: 12 Litre Insulated Lunch Box Grey | B22: 980 | C22: 1490 | D22: 0.34 | E22: 12 | F22: 4.7 | G22: =IF(F22="",NA(),F22) -> 4.7 | H22: =IF(F22="",NA(),E22) -> 12 | I22: =IF(F22="",NA(),B22) -> 980 | J22: =IF(F22="",NA(),F22) -> 4.7 | L22: 120W Cordless Vacuum Cleaners Handheld Electric Vacuum Cleaner | M22: 69
A23: Genebre 115 In 1 Screwdriver Repairing Tool Set For IPhone Cellphone Hand Tool | B23: 799 | C23: 999 | D23: 0.2 | E23: 12 | F23: 4.1 | G23: =IF(F23="",NA(),F23) -> 4.1 | H23: =IF(F23="",NA(),E23) -> 12 | I23: =IF(F23="",NA(),B23) -> 799 | J23: =IF(F23="",NA(),F23) -> 4.1 | L23: 137 Pieces Cake Decorating Tool Set Baking Supplies | M23: 55
A24: Portable Wardrobe Nonwoven With 3 Hanging Rods And 6 Storage Shelves | B24: 2880 | C24: 3520 | D24: 0.18 | E24: 12 | F24: 3.8 | G24: =IF(F24="",NA(),F24) -> 3.8 | H24: =IF(F24="",NA(),E24) -> 12 | I24: =IF(F24="",NA(),B24) -> 2880 | J24: =IF(F24="",NA(),F24) -> 3.8 | L24: Electronic Digital Display Vernier Caliper | M24: 49
A25: Mythco 120COB Solar Wall Ligt With Motion Sensor And Remote Control 3 Modes | B25: 458 | C25: 986 | D25: 0.54 | E25: 10 | F25: 3 | G25: =IF(F25="",NA(),F25) -> 3 | H25: =IF(F25="",NA(),E25) -> 10 | I25: =IF(F25="",NA(),B25) -> 458 | J25: =IF(F25="",NA(),F25) -> 3 | L25: 3D Waterproof EVA Plastic Shower Curtain 1.8*2Mtrs | M25: 44
A26: Exfoliate And Exfoliate Face Towel - Black | B26: 185 | C26: 382 | D26: 0.52 | E26: 9 | F26: 4.3 | G26: =IF(F26="",NA(),F26) -> 4.3 | H26: =IF(F26="",NA(),E26) -> 9 | I26: =IF(F26="",NA(),B26) -> 185 | J26: =IF(F26="",NA(),F26) -> 4.3 | L26: 100 Pcs Crochet Hook Tool Set Knitting Hook Set With Box | M26: 39
A27: LED Eye Protection Desk Lamp , Study, Reading, USB Fan - Double Pen Holder | B27: 1820 | C27: 3490 | D27: 0.48 | E27: 9 | F27: 4.3 | G27: =IF(F27="",NA(),F27) -> 4.3 | H27: =IF(F27="",NA(),E27) -> 9 | I27: =IF(F27="",NA(),B27) -> 1820 | J27: =IF(F27="",NA(),F27) -> 4.3 | L27: Punch-free Great Load Bearing Bathroom Storage Rack Wall Shelf-White | M27: 36
A28: Multifunction Laser Level With Adjustment Tripod | B28: 1680 | C28: 2499 | D28: 0.33 | E28: 9 | F28: 4.2 | G28: =IF(F28="",NA(),F28) -> 4.2 | H28: =IF(F28="",NA(),E28) -> 9 | I28: =IF(F28="",NA(),B28) -> 1680 | J28: =IF(F28="",NA(),F28) -> 4.2 | L28: 53 Pieces/Set Yarn Knitting Crochet Hooks With Bag - Pansies | M28: 32
A29: LASA 3 Tier Bamboo Shoe Bench Storage Shelf | B29: 2048 | C29: 4500 | D29: 0.54 | E29: 7 | F29: 4.3 | G29: =IF(F29="",NA(),F29) -> 4.3 | H29: =IF(F29="",NA(),E29) -> 7 | I29: =IF(F29="",NA(),B29) -> 2048 | J29: =IF(F29="",NA(),F29) -> 4.3 | L29: Portable Mini Cordless Car Vacuum Cleaner - Blue | M29: 24
A30: 380ML USB Rechargeable Portable Small Blenders And Juicers | B30: 1000 | C30: 2000 | D30: 0.5 | E30: 7 | F30: 2.3 | G30: =IF(F30="",NA(),F30) -> 2.3 | H30: =IF(F30="",NA(),E30) -> 7 | I30: =IF(F30="",NA(),B30) -> 1000 | J30: =IF(F30="",NA(),F30) -> 2.3 | L30: 52 Pieces Cake Decorating Tool Set Gift Kit Baking Supplies | M30: 20
A31: Electric LED UV Mosquito Killer Lamp, Outdoor/Indoor Fly Killer Trap Light -USB | B31: 1570 | C31: 2988 | D31: 0.47 | E31: 7 | F31: 2.1 | G31: =IF(F31="",NA(),F31) -> 2.1 | H31: =IF(F31="",NA(),E31) -> 7 | I31: =IF(F31="",NA(),B31) -> 1570 | J31: =IF(F31="",NA(),F31) -> 2.1 | L31: 53Pcs/Set Yarn Knitting Crochet Hooks With Bag - Fortune Cat | M31: 20
A32: Weighing Scale Digital Bathroom Body Fat Scale USB-Black | B32: 1580 | C32: 2499 | D32: 0.37 | E32: 7 | F32: 4.7 | G32: =IF(F32="",NA(),F32) -> 4.7 | H32: =IF(F32="",NA(),E32) -> 7 | I32: =IF(F32="",NA(),B32) -> 1580 | J32: =IF(F32="",NA(),F32) -> 4.7
A33: 7-piece Set Of Storage Bags, Travel Storage Bags, Shoe Bags | B33: 968 | C33: 1814 | D33: 0.47 | E33: 6 | F33: 2.2 | G33: =IF(F33="",NA(),F33) -> 2.2 | H33: =IF(F33="",NA(),E33) -> 6 | I33: =IF(F33="",NA(),B33) -> 968 | J33: =IF(F33="",NA(),F33) -> 2.2 | L33: Top 10 by Rating
A34: Artificial Potted Flowers Room Decorative Flowers (2 Pieces) | B34: 990 | C34: 1814 | D34: 0.45 | E34: 6 | F34: 2.2 | G34: =IF(F34="",NA(),F34) -> 2.2 | H34: =IF(F34="",NA(),E34) -> 6 | I34: =IF(F34="",NA(),B34) -> 990 | J34: =IF(F34="",NA(),F34) -> 2.2 | L34: Product | N34: Rating
A35: Watercolour Gold Foil Textured Print Pillow Cover | B35: 345 | C35: 602 | D35: 0.43 | E35: 6 | F35: 2.3 | G35: =IF(F35="",NA(),F35) -> 2.3 | H35: =IF(F35="",NA(),E35) -> 6 | I35: =IF(F35="",NA(),B35) -> 345 | J35: =IF(F35="",NA(),F35) -> 2.3 | L35: LASA Aluminum Folding Truck Hand Cart - 68kg Max | N35: 5
A36: LASA Digital Thermometer And Hydrometer | B36: 501 | C36: 860 | D36: 0.42 | E36: 6 | F36: 4.5 | G36: =IF(F36="",NA(),F36) -> 4.5 | H36: =IF(F36="",NA(),E36) -> 6 | I36: =IF(F36="",NA(),B36) -> 501 | J36: =IF(F36="",NA(),F36) -> 4.5 | L36: Classic Black Cat Cotton Hemp Pillow Case For Home Car | N36: 5
A37: LED Romantic Spaceship Starry Sky Projector,Children's Bedroom Night Light-Blue | B37: 880 | C37: 1350 | D37: 0.35 | E37: 6 | F37: 4 | G37: =IF(F37="",NA(),F37) -> 4 | H37: =IF(F37="",NA(),E37) -> 6 | I37: =IF(F37="",NA(),B37) -> 880 | J37: =IF(F37="",NA(),F37) -> 4 | L37: Anti-Skid Absorbent Insulation Coaster For Home Office | N37: 5
A38: 5 Pieces/set Of Stainless Steel Induction Cooker Pots | B38: 2170 | C38: 2500 | D38: 0.13 | E38: 6 | F38: 2.5 | G38: =IF(F38="",NA(),F38) -> 2.5 | H38: =IF(F38="",NA(),E38) -> 6 | I38: =IF(F38="",NA(),B38) -> 2170 | J38: =IF(F38="",NA(),F38) -> 2.5 | L38: Peacock Throw Pillow Cushion Case For Home Car | N38: 5
A39: LASA FOLDING TABLE SERVING STAND | B39: 1274 | C39: 2800 | D39: 0.55 | E39: 5 | F39: 4.8 | G39: =IF(F39="",NA(),F39) -> 4.8 | H39: =IF(F39="",NA(),E39) -> 5 | I39: =IF(F39="",NA(),B39) -> 1274 | J39: =IF(F39="",NA(),F39) -> 4.8 | L39: Bedroom Simple Floor Hanging Clothes Rack Single Pole Hat Rack - White | N39: 5
A40: 13 In 1 Home Repair Tools Box Kit Set | B40: 1600 | C40: 2929 | D40: 0.45 | E40: 5 | F40: 3.8 | G40: =IF(F40="",NA(),F40) -> 3.8 | H40: =IF(F40="",NA(),E40) -> 5 | I40: =IF(F40="",NA(),B40) -> 1600 | J40: =IF(F40="",NA(),F40) -> 3.8 | L40: DIY File Folder, Office Drawer File Holder, Pen Holder, Desktop Storage Rack | N40: 5
...

Sheet  Analysis Tables
B1: Correlation | C1: R2
A2: Discount vs Reviews | B2: 0.012188797 | C2: 0.0001
A3: Rating vs Reviews | B3: 0.057209035 | C3: 0.0033
A4: Current Price vs Rating | B4: 0.11009021 | C4: 0.0121
A7: Top 10 by Discount
A8: Product | B8: Discount
A9: 6 In 1 Bottle Can Opener Multifunctional Easy Opener | B9: 0.64
A10: Creative Owl Shape Keychain Black | B10: 0.61
A11: LASA FOLDING TABLE SERVING STAND | B11: 0.55
A12: Simple Metal Dog Art Sculpture Decoration For Home Office | B12: 0.55
A13: 5-PCS Stainless Steel Cooking Pot Set With Steamed Slices | B13: 0.55
A14: LASA 3 Tier Bamboo Shoe Bench Storage Shelf | B14: 0.54
A15: Mythco 120COB Solar Wall Ligt With Motion Sensor And Remote Control 3 Modes | B15: 0.54
A16: 3PCS Single Head Knitting Crochet Sweater Needle Set | B16: 0.53
A17: Classic Black Cat Cotton Hemp Pillow Case For Home Car | B17: 0.53
A18: Exfoliate And Exfoliate Face Towel - Black | B18: 0.52
A20: Top 10 by Reviews
A21: Product | B21: Review
A22: 120W Cordless Vacuum Cleaners Handheld Electric Vacuum Cleaner | B22: 69
A23: 137 Pieces Cake Decorating Tool Set Baking Supplies | B23: 55
A24: Electronic Digital Display Vernier Caliper | B24: 49
A25: 3D Waterproof EVA Plastic Shower Curtain 1.8*2Mtrs | B25: 44
A26: 100 Pcs Crochet Hook Tool Set Knitting Hook Set With Box | B26: 39
A27: Punch-free Great Load Bearing Bathroom Storage Rack Wall Shelf-White | B27: 36
A28: 53 Pieces/Set Yarn Knitting Crochet Hooks With Bag - Pansies | B28: 32
A29: Portable Mini Cordless Car Vacuum Cleaner - Blue | B29: 24
A30: 52 Pieces Cake Decorating Tool Set Gift Kit Baking Supplies | B30: 20
A31: 53Pcs/Set Yarn Knitting Crochet Hooks With Bag - Fortune Cat | B31: 20
A33: Top 10 by Rating
A34: Product | B34: Rating
A35: LASA Aluminum Folding Truck Hand Cart - 68kg Max | B35: 5
A36: Classic Black Cat Cotton Hemp Pillow Case For Home Car | B36: 5
A37: Anti-Skid Absorbent Insulation Coaster For Home Office | B37: 5
A38: Peacock Throw Pillow Cushion Case For Home Car | B38: 5
A39: Bedroom Simple Floor Hanging Clothes Rack Single Pole Hat Rack - White | B39: 5
A40: DIY File Folder, Office Drawer File Holder, Pen Holder, Desktop Storage Rack | B40: 5
A41: Konka Healty Electric Kettle, 24-hour Heat Preservation,1.5L,800W, White | B41: 5
A42: 40cm Gold DIY Acrylic Wall Sticker Clock | B42: 4.8
A43: LASA FOLDING TABLE SERVING STAND | B43: 4.8
A44: Portable Home Small Air Humidifier 3-Speed Fan - Green | B44: 4.8
...

Sheet Pivot Charts

Sheet Pivot Tables
A1: Discount Category vs Reviews
A2: Row Labels | B2: Average of Review
A3: Low | B3: 2.1111111
A4: Medium | B4: 10.96875
A5: High | B5: 5.3870968
A6: Grand Total | B6: 6.4553571
A9: Rating Category vs Reviews
A10: Row Labels | B10: Average of Review
A11: Poor | B11: 14.083333
A12: Average | B12: 7.1538462
A13: Good | B13: 13.230769
A14: Excellent | B14: 15.210526
A15: Not Rated | B15: 0
A16: Grand Total | B16: 6.4553571
A19: Price Category vs Rating
A20: Row Labels | B20: Average of Rating
A21: Low | B21: 3.6357143
A22: Medium | B22: 3.8833333
A23: High | B23: 4.0842105
A24: Grand Total | B24: 3.8894737
A27: Discount Category × Rating Category
A28: Count of Product | B28: Column Labels
A29: Row Labels | B29: High | C29: Low | D29: Medium | E29: Grand Total
A30: Average | B30: 6 | C30: 2 | D30: 5 | E30: 13
A31: Excellent | B31: 8 | C31: 1 | D31: 10 | E31: 19
A32: Good | B32: 6 | D32: 7 | E32: 13
A33: Not Rated | B33: 32 | C33: 14 | D33: 9 | E33: 55
A34: Poor | B34: 10 | C34: 1 | D34: 1 | E34: 12
A35: Grand Total | B35: 62 | C35: 18 | D35: 32 | E35: 112
A37: Top 10 Items by Sum of Review
A38: Product | B38: Sum of Review
A39: 120W Cordless Vacuum Cleaners Handheld Electric Vacuum Cleaner | B39: 69
A40: 137 Pieces Cake Decorating Tool Set Baking Supplies | B40: 55
A41: Electronic Digital Display Vernier Caliper | B41: 49
A42: 3D Waterproof EVA Plastic Shower Curtain 1.8*2Mtrs | B42: 44
A43: 100 Pcs Crochet Hook Tool Set Knitting Hook Set With Box | B43: 39
A44: Punch-free Great Load Bearing Bathroom Storage Rack Wall Shelf-White | B44: 36
A45: 53 Pieces/Set Yarn Knitting Crochet Hooks With Bag - Pansies | B45: 32
A46: Portable Mini Cordless Car Vacuum Cleaner - Blue | B46: 24
A47: 53Pcs/Set Yarn Knitting Crochet Hooks With Bag - Fortune Cat | B47: 20
...

Sheet Exception
A1: High Discount + Poor Rating
A2: Product | B2: Current price | C2: Discount | D2: Review | E2: Rating | F2: Discount Amount | G2: Rating Category | H2: Discount Category | I2: Price Category
A3: 120W Cordless Vacuum Cleaners Handheld Electric Vacuum Cleaner | B3: 445 | C3: 0.49 | D3: 69 | E3: 2.8 | F3: 428 | G3: Poor | H3: High | I3: Low
A4: Agapeon Toothbrush Holder And Toothpaste Dispenser | B4: 382 | C4: 0.45 | D4: 17 | E4: 2.6 | F4: 318 | G4: Poor | H4: High | I4: Low
A5: Intelligent LED Body Sensor Wireless Lighting Night Light USB | B5: 325 | C5: 0.52 | D5: 15 | E5: 2.7 | F5: 355 | G5: Poor | H5: High | I5: Low
A6: 5-PCS Stainless Steel Cooking Pot Set With Steamed Slices | B6: 2115 | C6: 0.55 | D6: 13 | E6: 2.1 | F6: 2585 | G6: Poor | H6: High | I6: High
A7: 380ML USB Rechargeable Portable Small Blenders And Juicers | B7: 1000 | C7: 0.5 | D7: 7 | E7: 2.3 | F7: 1000 | G7: Poor | H7: High | I7: Medium
A8: Electric LED UV Mosquito Killer Lamp, Outdoor/Indoor Fly Killer Trap Light -USB | B8: 1570 | C8: 0.47 | D8: 7 | E8: 2.1 | F8: 1418 | G8: Poor | H8: High | I8: Medium
A9: Artificial Potted Flowers Room Decorative Flowers (2 Pieces) | B9: 990 | C9: 0.45 | D9: 6 | E9: 2.2 | F9: 824 | G9: Poor | H9: High | I9: Medium
A10: Watercolour Gold Foil Textured Print Pillow Cover | B10: 345 | C10: 0.43 | D10: 6 | E10: 2.3 | F10: 257 | G10: Poor | H10: High | I10: Low
A11: 7-piece Set Of Storage Bags, Travel Storage Bags, Shoe Bags | B11: 968 | C11: 0.47 | D11: 6 | E11: 2.2 | F11: 846 | G11: Poor | H11: High | I11: Medium
A12: Wall-mounted Sticker Punch-free Plug Fixer | B12: 450 | C12: 0.5 | D12: 1 | E12: 2 | F12: 450 | G12: Poor | H12: High | I12: Low
A16: High Discount + Little Engagement
A17: Product | B17: Current price | C17: Discount | D17: Review | E17: Rating | F17: Discount Amount | G17: Rating Category | H17: Discount Category | I17: Price Category
A18: 4pcs Bathroom/Kitchen Towel Rack,Roll Paper Holder,Towel Bars,Hook | B18: 1860 | C18: 0.42 | D18: 0 | F18: 1360 | G18: Not Rated | H18: High | I18: High
A19: MultiFunctional Storage Rack Multi-layer Bookshelf | B19: 2200 | C19: 0.46 | D19: 0 | F19: 1880 | G19: Not Rated | H19: High | I19: High
A20: 4M Float Switch Water Level Controller -Water Tank | B20: 475 | C20: 0.49 | D20: 0 | F20: 456 | G20: Not Rated | H20: High | I20: Low
A21: Modern Sofa Throw Pillow Cover-45x45cm-Blue&Red | B21: 238 | C21: 0.5 | D21: 0 | F21: 238 | G21: Not Rated | H21: High | I21: Low
A22: Balloon Insert, Birthday Party Balloon Set, PU Leather | B22: 610 | C22: 0.42 | D22: 0 | F22: 450 | G22: Not Rated | H22: High | I22: Medium
A23: Christmas Elk Fence Yard Lawn Decorations Cute For Holidays | B23: 999 | C23: 0.5 | D23: 0 | F23: 1001 | G23: Not Rated | H23: High | I23: Medium
A24: Car Phone Charging Stand | B24: 671 | C24: 0.49 | D24: 0 | F24: 645 | G24: Not Rated | H24: High | I24: Medium
A25: Creative Owl Shape Keychain Black | B25: 199 | C25: 0.61 | D25: 0 | F25: 305 | G25: Not Rated | H25: High | I25: Low
A26: Brush & Paintbrush Cleaning Tool Pink | B26: 299 | C26: 0.5 | D26: 0 | F26: 301 | G26: Not Rated | H26: High | I26: Low
A27: Cute Christmas Fence Garden Decorations For Holiday Home | B27: 799 | C27: 0.41 | D27: 0 | F27: 544 | G27: Not Rated | H27: High | I27: Medium
A28: Simple Metal Dog Art Sculpture Decoration For Home Office | B28: 499 | C28: 0.45 | D28: 0 | F28: 401 | G28: Not Rated | H28: High | I28: Medium
A29: Christmas Fence Garden Decorations Outdoor For Holiday Home | B29: 699 | C29: 0.48 | D29: 0 | F29: 644 | G29: Not Rated | H29: High | I29: Medium
... A49: Black Simple Water Cup Wine Coaster Anti Slip Absorbent | B49: 169 | C49: 0.47 | D49: 0 | F49: 151 | G49: Not Rated | H49: High | I49: Low
A52: Strong Demand + Average Rating
A53: Product | B53: Current price | C53: Discount | D53: Review | E53: Rating | F53: Discount Amount | G53: Rating Category | H53: Discount Category | I53: Price Category
A54: 220V 60W Electric Soldering Iron Kits With Tools, Tips, And Multimeter | B54: 2999 | C54: 0.09 | D54: 15 | E54: 4 | F54: 291 | G54: Average | H54: Low | I54: High
A55: 3PCS Single Head Knitting Crochet Sweater Needle Set | B55: 38 | C55: 0.53 | D55: 13 | E55: 3.3 | F55: 42 | G55: Average | H55: High | I55: Low
A56: 12 Litre Black Insulated Lunch Box | B56: 1350 | C56: 0.32 | D56: 13 | E56: 3.8 | F56: 640 | G56: Average | H56: Medium | I56: Medium
A57: Portable Wardrobe Nonwoven With 3 Hanging Rods And 6 Storage Shelves | B57: 2880 | C57: 0.18 | D57: 12 | E57: 3.8 | F57: 640 | G57: Average | H57: Low | I57: High
A58: Mythco 120COB Solar Wall Ligt With Motion Sensor And Remote Control 3 Modes | B58: 458 | C58: 0.54 | D58: 10 | E58: 3 | F58: 528 | G58: Average | H58: High | I58: Low
A61: High Price + Poor Rating
A62: Product | B62: Current price | C62: Old price | D62: Discount | E62: Review | F62: Rating | G62: Discount Amount | H62: Rating Category | I62: Discount Category | J62: Price Category
A63: 5-PCS Stainless Steel Cooking Pot Set With Steamed Slices | B63: 2115 | C63: 4700 | D63: 0.55 | E63: 13 | F63: 2.1 | G63: 2585 | H63: Poor | I63: High | J63: High
A64: 5 Pieces/set Of Stainless Steel Induction Cooker Pots | B64: 2170 | C64: 2500 | D64: 0.13 | E64: 6 | F64: 2.5 | G64: 330 | H64: Poor | I64: Low | J64: High
